<?xml version="1.0"?>
<robot name="my_robot">

  <!-- Add a base footprint definition -->
  <joint name="base_footprint_joint" type="fixed">
    <parent link="base_link"/>
    <child link="base_footprint"/>
    <origin rpy="0 0 0" xyz="0 0 0.0"/>
  </joint>
  <link name="base_footprint">
    <inertial>
      <mass value="0.0001"/>
      <origin xyz="0 0 0"/>
      <inertia ixx="0.0001" ixy="0.0" ixz="0.0" iyy="0.0001" iyz="0.0" izz="0.0001"/>
    </inertial>
    <visual>
      <origin rpy="0 0 0" xyz="0 0 0"/>
      <geometry>
        <box size="0.001 0.001 0.001"/>
      </geometry>
    </visual>
  </link>

  <!-- Base of the robot -->
<link name="base_link">
    <visual>
        <origin xyz="0 0 0" rpy="0 0 0"/>
        <geometry>
            <mesh filename="file:///home/andi/project/ros2_workspace/src/self_driving_bot/meshes/robot.stl" scale="0.001 0.001 0.001"/>
        </geometry>
        <material name="wood">
            <color rgba="0.6 0.4 0.2 1.0"/>
        </material>
    </visual>

    <collision>
        <origin xyz="0 0 0.105" rpy="0 0 0"/>
        <geometry>
            <mesh filename="file:///home/andi/project/ros2_workspace/src/self_driving_bot/meshes/robot.stl" scale="0.001 0.001 0.001"/>
        </geometry>
    </collision>

    <inertial>
        <origin xyz="0 0 0" rpy="0 0 0"/>
        <mass value="0.25"/>
        <inertia ixx="0.00027539" ixy="0" ixz="0" iyy="0.00052463" iyz="0" izz="0.00027551"/>
    </inertial>
</link>

  <!-- Right wheel -->
  <link name="right_wheel">
    <visual>
      <origin xyz="0 0 0" rpy="0 0 0"/>
      <geometry>
        <cylinder radius="0.032" length="0.02"/>
      </geometry>
      <material name="black">
        <color rgba="0 0 0 1.0"/>
      </material>
    </visual>
    <collision>
      <origin xyz="0 0 0" rpy="0 0 0"/>
      <geometry>
        <cylinder radius="0.032" length="0.02"/>
      </geometry>
    </collision>
    <inertial>
      <origin xyz="0 0 0" rpy="0 0 0"/>
      <mass value="0.1"/> <!-- Setze die Masse des Rades -->
      <inertia ixx="0.0001" ixy="0" ixz="0" iyy="0.0001" iyz="0" izz="0.0001"/> <!-- Schätze die Trägheitswerte -->
    </inertial>
  </link>

  <!-- Left wheel -->
  <link name="left_wheel">
    <visual>
      <origin xyz="0 0 0" rpy="0 0 0"/>
      <geometry>
        <cylinder radius="0.032" length="0.02"/>
      </geometry>
      <material name="black">
        <color rgba="0 0 0 1.0"/>
      </material>
    </visual>
    <collision>
      <origin xyz="0 0 0" rpy="0 0 0"/>
      <geometry>
        <cylinder radius="0.032" length="0.02"/>
      </geometry>
    </collision>
    <inertial>
      <origin xyz="0 0 0" rpy="0 0 0"/>
      <mass value="0.1"/> <!-- Setze die Masse des Rades -->
      <inertia ixx="0.0001" ixy="0" ixz="0" iyy="0.0001" iyz="0" izz="0.0001"/> <!-- Schätze die Trägheitswerte -->
    </inertial>
  </link>

  <!-- Right wheel -->
  <link name="right_front_wheel">
    <visual>
      <origin xyz="0 0 0" rpy="0 0 0"/>
      <geometry>
        <cylinder radius="0.032" length="0.02"/>
      </geometry>
      <material name="black">
        <color rgba="0 0 0 1.0"/>
      </material>
    </visual>
    <collision>
      <origin xyz="0 0 0" rpy="0 0 0"/>
      <geometry>
        <cylinder radius="0.032" length="0.02"/>
      </geometry>
    </collision>
    <inertial>
      <origin xyz="0 0 0" rpy="0 0 0"/>
      <mass value="0.1"/> <!-- Setze die Masse des Rades -->
      <inertia ixx="0.0001" ixy="0" ixz="0" iyy="0.0001" iyz="0" izz="0.0001"/> <!-- Schätze die Trägheitswerte -->
    </inertial>
  </link>

  <!-- Left wheel -->
  <link name="left_front_wheel">
    <visual>
      <origin xyz="0 0 0" rpy="0 0 0"/>
      <geometry>
        <cylinder radius="0.032" length="0.02"/>
      </geometry>
      <material name="black">
        <color rgba="0 0 0 1.0"/>
      </material>
    </visual>
    <collision>
      <origin xyz="0 0 0" rpy="0 0 0"/>
      <geometry>
        <cylinder radius="0.032" length="0.02"/>
      </geometry>
    </collision>
    <inertial>
      <origin xyz="0 0 0" rpy="0 0 0"/>
      <mass value="0.1"/> <!-- Setze die Masse des Rades -->
      <inertia ixx="0.0001" ixy="0" ixz="0" iyy="0.0001" iyz="0" izz="0.0001"/> <!-- Schätze die Trägheitswerte -->
    </inertial>
  </link>

  <!-- Joints -->
  <joint name="right_wheel_joint" type="continuous">
    <parent link="base_link"/>
    <child link="right_wheel"/>
    <origin xyz="-0.070 0.062 0" rpy="1.5708 0 0"/>
    <axis xyz="0 0 -1"/>
  </joint>

  <joint name="left_wheel_joint" type="continuous">
    <parent link="base_link"/>
    <child link="left_wheel"/>
    <origin xyz="-0.070 -0.062 0" rpy="1.5708 0 0"/>
    <axis xyz="0 0 -1"/>
  </joint>

  <joint name="right_front_wheel_joint" type="continuous">
    <parent link="base_link"/>
    <child link="right_front_wheel"/>
    <origin xyz="0.070 0.060 0" rpy="1.5708 0 0"/>
    <axis xyz="0 0 -1"/>
  </joint>

  <joint name="left_front_wheel_joint" type="continuous">
    <parent link="base_link"/>
    <child link="left_front_wheel"/>
    <origin xyz="0.070 -0.060 0" rpy="1.5708 0 0"/>
    <axis xyz="0 0 -1"/>
  </joint>


  <!-- Gazebo joint_state_publisher plugin -->
  <gazebo>
    <plugin filename="gz-sim-joint-state-publisher-system" name="gz::sim::systems::JointStatePublisher">
      <joint_name>right_wheel_joint</joint_name>
      <joint_name>left_wheel_joint</joint_name>
      <joint_name>right_front_wheel_joint</joint_name>
      <joint_name>left_front_wheel_joint</joint_name>
      <topic>joint_states</topic>
      <update_rate>30</update_rate>
    </plugin>
  </gazebo>

  <gazebo>
    <plugin filename="gz-sim-diff-drive-system" name="gz::sim::systems::DiffDrive">
      <!-- Definieren der Gelenke für die beiden Räder -->
      <left_joint>left_wheel_joint</left_joint>
      <right_joint>right_wheel_joint</right_joint>
  

      <!-- Anpassung der Radtrennung und des Radradius auf die Robotergröße -->
      <wheel_separation>0.20</wheel_separation> <!-- Abstand zwischen den Rädern (Breite des Roboters) -->
      <wheel_radius>0.035</wheel_radius> <!-- Radius der Räder (Durchmesser = 0.07m) -->

      <!-- Maximale und minimale Beschleunigungen und Geschwindigkeiten -->
      <max_linear_acceleration>2</max_linear_acceleration>
      <min_linear_acceleration>-2</min_linear_acceleration>
      <max_angular_acceleration>3</max_angular_acceleration>
      <min_angular_acceleration>-3</min_angular_acceleration>

      <max_linear_velocity>0.5</max_linear_velocity>
      <min_linear_velocity>-0.5</min_linear_velocity>
      <max_angular_velocity>0.75</max_angular_velocity>
      <min_angular_velocity>-0.75</min_angular_velocity>

      <!-- Definieren der Steuerungs- und Odometrie-Themen -->
      <topic>/cmd_vel</topic>
      <odom_topic>/odom</odom_topic>
      <tf_topic>tf</tf_topic>

      <!-- Definition des Rahmens für Odometrie -->
      <frame_id>odom</frame_id>
      <child_frame_id>base_link</child_frame_id>

      <!-- Häufigkeit der Odometrie-Publikation -->
      <odom_publish_frequency>30</odom_publish_frequency>
    </plugin>
  </gazebo>

  <!-- Transmissions for ros2_control -->
  <transmission name="left_wheel_trans">
    <type>transmission_interface/SimpleTransmission</type>
    <joint name="left_wheel_joint">
      <hardwareInterface>hardware_interface/VelocityJointInterface</hardwareInterface>
    </joint>
    <actuator name="left_wheel_motor">
      <hardwareInterface>hardware_interface/VelocityJointInterface</hardwareInterface>
    </actuator>
  </transmission>

  <transmission name="right_wheel_trans">
    <type>transmission_interface/SimpleTransmission</type>
    <joint name="right_wheel_joint">
      <hardwareInterface>hardware_interface/VelocityJointInterface</hardwareInterface>
    </joint>
    <actuator name="right_wheel_motor">
      <hardwareInterface>hardware_interface/VelocityJointInterface</hardwareInterface>
    </actuator>
  </transmission>

    <!-- ros2_control Block -->
  <ros2_control name="MyRobotHardware" type="system">
    <hardware>
      <plugin>mock_components/GenericSystem</plugin>  <!-- Falls du eine Simulation machst -->
      <param name="joints">
        <joint name="left_wheel_joint">
          <command_interface name="velocity"/>
          <state_interface name="velocity"/>
        </joint>
        <joint name="right_wheel_joint">
          <command_interface name="velocity"/>
          <state_interface name="velocity"/>
        </joint>
      </param>
    </hardware>
  </ros2_control>

</robot>
