<robot name="minimal_robot">

  <!-- Base Link -->
  <link name="base_link"/>
  
  <!-- Left Wheel -->
  <link name="left_wheel"/>
  
  <!-- Right Wheel -->
  <link name="right_wheel"/>

  <!-- Left Wheel Joint -->
  <joint name="left_wheel_joint" type="continuous">
    <parent link="base_link"/>
    <child link="left_wheel"/>
    <axis xyz="0 1 0"/> <!-- Rotiert um die Y-Achse -->
  </joint>

  <!-- Right Wheel Joint -->
  <joint name="right_wheel_joint" type="continuous">
    <parent link="base_link"/>
    <child link="right_wheel"/>
    <axis xyz="0 1 0"/> <!-- Rotiert um die Y-Achse -->
  </joint>

  <!-- Transmission for Left Wheel -->
  <transmission name="left_wheel_trans">
    <type>transmission_interface/SimpleTransmission</type>
    <joint name="left_wheel_joint">
      <hardwareInterface>hardware_interface/VelocityJointInterface</hardwareInterface>
    </joint>
    <actuator name="left_wheel_motor">
      <hardwareInterface>hardware_interface/VelocityJointInterface</hardwareInterface>
    </actuator>
  </transmission>

  <!-- Transmission for Right Wheel -->
  <transmission name="right_wheel_trans">
    <type>transmission_interface/SimpleTransmission</type>
    <joint name="right_wheel_joint">
      <hardwareInterface>hardware_interface/VelocityJointInterface</hardwareInterface>
    </joint>
    <actuator name="right_wheel_motor">
      <hardwareInterface>hardware_interface/VelocityJointInterface</hardwareInterface>
    </actuator>
  </transmission>

  <!-- ros2_control Block -->
  <ros2_control name="MyRobotHardware" type="system">
    <hardware>
      <plugin>mock_components/GenericSystem</plugin>  <!-- Falls du eine Simulation machst -->
      <param name="joints">
        <joint name="left_wheel_joint">
          <command_interface name="velocity"/>
          <state_interface name="velocity"/>
        </joint>
        <joint name="right_wheel_joint">
          <command_interface name="velocity"/>
          <state_interface name="velocity"/>
        </joint>
      </param>
    </hardware>
  </ros2_control>

</robot>
